Workbook

Sheet Planilha1
A1: VENDEDOR | B1: DATA DE ENTRADA | C1: GRUPO DE CLIENTE | D1: PEDIDO | E1: CLIENTE | F1: PRODUTO | G1: GRUPO | H1: LINHA | I1: QUANTIDADE | J1: PREÇO UNITARIO | K1: TOTAL | L1: DATA DE ENTREGA | M1: STATUS | N1: DATA DE SAIDA | O1: MATERIA PRIMA | P1: CORTE | Q1: SILK | R1: COSTURA | S1: EMBALAGEM | T1: NF | U1: ENTREGA
A2: LETICIA | B2: 45538 | C2: COSMÉTICO | D2: 598 | E2: GARDEN INDUSTRIA | F2: CAPA DE CORTE CETIM 1,47A X 1,20L SUBLIMADA COM ZIPER | G2: CAPA | H2: LEVE | I2: 300 | J2: 28 | K2: =I2*J2 -> 8400 | L2: 45567 | M2: =IF(L2<TODAY(),"ATRASO","EM PRODUÇÃO") -> ATRASO | N2: FALTA 54 PEÇAS | O2: OK | P2: OK | Q2: OK | R2: OK | S2: OK | T2: 970 | U2: ENTREGUE
A3: LETICIA | B3: 45553 | C3: COSMÉTICO | D3: 180 | E3: NB COSMÉTICOS (D BIANCO) | F3: KIMONO CETIM - TAM ÚNICO | G3: KIMONO | H3: LEVE | I3: 100 | J3: 26.5 | K3: =I3*J3 -> 2650 | L3: 45580 | M3: =IF(L3<TODAY(),"ATRASO","EM PRODUÇÃO") -> ATRASO | N3: 45589 | O3: OK | P3: OK | Q3: OK | R3: OK | S3: OK | T3: OK | U3: ENTREGUE
A4: LETICIA | B4: 45552 | C4: PET | D4: 176 | E4: PETCO CLEAN & CARE (PETCO) | F4: CAMISETA POLO MALHA PIQUET | G4: CAMISETA | H4: LEVE | I4: 10 | J4: 75 | K4: =I4*J4 -> 750 | L4: 45580 | M4: =IF(L4<TODAY(),"ATRASO","EM PRODUÇÃO") -> ATRASO | N4: 45594 | O4: OK | P4: OK | Q4: OK | R4: OK | S4: OK | T4: 154 | U4: ENTREGUE
A5: LETICIA | B5: 45552 | C5: PET | D5: 177 | E5: PETCO CLEAN & CARE (PETCO) | F5: JALECO MICROFIBRA COM TAFETA- PETCO | G5: JALECO | H5: LEVE | I5: 210 | J5: 55 | K5: =I5*J5 -> 11550 | L5: 45580 | M5: =IF(L5<TODAY(),"ATRASO","EM PRODUÇÃO") -> ATRASO | N5: 45596 | O5: OK | P5: OK | Q5: OK | R5: OK | S5: OK | T5: OK | U5: ENTREGUE
A6: LETICIA | B6: 45552 | C6: CONSUMIDOR FINAL | D6: 179 | E6: NOEME SERRA PAIXÃO | F6: SACOLA NYLON 600 42L X 32A X 20 FOLY COM DIVISORIA | G6: SACOLA | H6: AMBAS | I6: 112 | J6: 23.5 | K6: =I6*J6 -> 2632 | L6: 45580 | M6: =IF(L6<TODAY(),"ATRASO","EM PRODUÇÃO") -> ATRASO | O6: OK | P6: OK | Q6: OK | R6: OK | S6: OK | T6: OK | U6: ENTREGUE
A7: LETICIA | B7: 45553 | C7: PET | D7: 181 | E7: CHEMVET (PETSPA) | F7: JALECO MICROFIBRA COM TAFETA- PETSPA | G7: JALECO | H7: LEVE | I7: 200 | J7: 55 | K7: =I7*J7 -> 11000 | L7: 45581 | M7: =IF(L7<TODAY(),"ATRASO","EM PRODUÇÃO") -> ATRASO | N7: 45602 | O7: OK | P7: OK | Q7: OK | R7: OK | S7: OK | T7: 159 | U7: ENTREGUE
A8: LETICIA | B8: 45572 | C8: COSMÉTICO | D8: 616 | E8: FLORA DISTRIBUIDORA | F8: CAMISETA MALHA PV GOLA CARECA | G8: CAMISETA | H8: LEVE | I8: 112 | J8: 26.5 | K8: =I8*J8 -> 2968 | L8: 45586 | M8: =IF(L8<TODAY(),"ATRASO","EM PRODUÇÃO") -> ATRASO | N8: 45587 | O8: OK | P8: OK | Q8: OK | R8: OK | S8: OK | T8: 959 | U8: ENTREGUE
A9: LETICIA | B9: 45560 | C9: COSMÉTICO | D9: 187 | E9: DUO INDUSTRIA (KPRO) | F9: AVENTAL GABARDINE MODELO PADRÃO | G9: AVENTAL | H9: LEVE | I9: 500 | J9: 19.5 | K9: =I9*J9 -> 9750 | L9: 45588 | M9: =IF(L9<TODAY(),"ATRASO","EM PRODUÇÃO") -> ATRASO | N9: 45600 | O9: OK | P9: OK | Q9: OK | R9: OK | S9: OK | T9: 158 | U9: ENTREGUE
A10: LETICIA | B10: 45574 | C10: COSMÉTICO | D10: 619 | E10: M.D BOSO PROHALL | F10: CAMISETA GOLA CARECA MALHA PV | G10: CAMISETA | H10: LEVE | I10: 34 | J10: 24.5 | K10: =I10*J10 -> 833 | L10: 45590 | M10: =IF(L10<TODAY(),"ATRASO","EM PRODUÇÃO") -> ATRASO | N10: 45588 | O10: OK | P10: OK | Q10: OK | R10: ok | S10: OK | T10: 961 | U10: ENTREGUE
A11: LETICIA | B11: 45565 | C11: EDITORA | D11: 1023 | E11: EDITORA RECORD | F11: SACOLA ALGODÃO CRU 35L X 40A | G11: SACOLA | H11: LEVE | I11: 400 | J11: 10.5 | K11: =I11*J11 -> 4200 | L11: 45593 | M11: =IF(L11<TODAY(),"ATRASO","EM PRODUÇÃO") -> ATRASO | O11: OK | P11: OK | Q11: OK | R11: OK | S11: OK | T11: OK | U11: ENTREGUE
A12: LETICIA | B12: 45561 | C12: COSMÉTICO | D12: 608 | E12: BR COSMETIC | F12: NECESSAIRE MALETA CRISTAL COLORIDO | G12: NECESSAIRE | H12: PESADA | I12: 1000 | J12: 15.5 | K12: =I12*J12 -> 15500 | L12: 45593 | M12: =IF(L12<TODAY(),"ATRASO","EM PRODUÇÃO") -> ATRASO | N12: 45588 | O12: OK | P12: OK | Q12: OK | R12: OK | S12: OK | T12: OK | U12: ENTREGUE
A13: DANIELE | B13: 45566 | C13: COSMÉTICO | D13: 190 | E13: FILO COSMETICOS | F13: NECESSAIRE CRISTAL COM VIES | G13: NECESSAIRE | H13: PESADA | I13: 100 | J13: 12 | K13: =I13*J13 -> 1200 | L13: 45594 | M13: =IF(L13<TODAY(),"ATRASO","EM PRODUÇÃO") -> ATRASO | N13: 41212 | O13: OK | P13: OK | Q13: OK | R13: OK | S13: OK | T13: OK | U13: ENTREGUE
A14: LETICIA | B14: 45565 | C14: PET | D14: 189 | E14: VET RIO | F14: AVENTAL SEMI IMPERMEAVEL | G14: AVENTAL | H14: LEVE | I14: 100 | J14: 19.7 | K14: =I14*J14 -> 1970 | L14: 45593 | M14: =IF(L14<TODAY(),"ATRASO","EM PRODUÇÃO") -> ATRASO | N14: 45596 | O14: OK | P14: OK | Q14: OK | R14: OK | S14: OK | T14: 157 | U14: ENTREGUE
A15: DANIELE | B15: 45566 | C15: COSMÉTICO | D15: 190 | E15: FILO COSMETICOS | F15: AVENTAL OXFORD MODELO PADRÃO | G15: AVENTAL | H15: LEVE | I15: 100 | J15: 17 | K15: =I15*J15 -> 1700 | L15: 45594 | M15: =IF(L15<TODAY(),"ATRASO","EM PRODUÇÃO") -> ATRASO | N15: 45595 | O15: OK | P15: OK | Q15: OK | R15: OK | S15: OK | T15: OK | U15: ENTREGUE
A16: LETICIA | B16: 45555 | C16: HAVANNA | D16: 1015 | E16: DOCES E DOCES (HAVANNA PRAIA DE BELLAS) | F16: CAMISETA GOLA CARECA MALHA 100% ALGODÃO | G16: CAMISETA | H16: LEVE | I16: =10+10+10+10+5 -> 45 | J16: 36.75 | K16: =I16*J16 -> 1653.75 | L16: 45593 | M16: =IF(L16<TODAY(),"ATRASO","EM PRODUÇÃO") -> ATRASO | O16: OK | P16: OK | Q16: OK | R16: OK | S16: OK | T16: OK | U16: ENTREGUE
A17: LETICIA | B17: 45567 | C17: COSMÉTICO | D17: 614 | E17: KOOSMETICS (EXO) | F17: NECESSSAIRE CRISTAL 30A X 16L X 10 - EXO | G17: NECESSAIRE | H17: PESADA | I17: 1500 | J17: 7.8 | K17: =I17*J17 -> 11700 | L17: 45595 | M17: =IF(L17<TODAY(),"ATRASO","EM PRODUÇÃO") -> ATRASO | N17: 45590 | O17: OK | P17: OK | Q17: OK | R17: OK | S17: OK | T17: 953 | U17: ENTREGUE
A18: LETICIA | B18: 45555 | C18: HAVANNA | D18: 1015 | E18: DOCES E DOCES (HAVANNA PRAIA DE BELLAS) | F18: CAMISETA FEMININA MALHA 100% ALGODÃO MANGA LONGA | G18: CAMISETA | H18: LEVE | I18: 45 | J18: 45 | K18: =I18*J18 -> 2025 | L18: 45593 | M18: =IF(L18<TODAY(),"ATRASO","EM PRODUÇÃO") -> ATRASO | O18: OK | P18: OK | Q18: OK | R18: OK | S18: OK | T18: OK | U18: ENTREGUE
A19: DANIELE | B19: 45579 | C19: HAVANNA | D19: 1033 | E19: ZF ALIMENTOS (HAVANNA MARILIA) | F19: BABY LOOK FEMININA MALHA 100% ALGODÃO | G19: CAMISETA | H19: LEVE | I19: =3+3+3+2 -> 11 | J19: 36.75 | K19: =I19*J19 -> 404.25 | L19: 45593 | M19: =IF(L19<TODAY(),"ATRASO","EM PRODUÇÃO") -> ATRASO | N19: 45593 | O19: OK | P19: OK | Q19: OK | R19: OK | S19: OK | T19: 1215 | U19: ENTREGUE
A20: DANIELE | B20: 45579 | C20: HAVANNA | D20: 1033 | E20: ZF ALIMENTOS (HAVANNA MARILIA) | F20: CAMISETA FEMININA MALHA 100% ALGODÃO MANGA LONGA | G20: CAMISETA | H20: LEVE | I20: 8 | J20: 47.5 | K20: =I20*J20 -> 380 | L20: 45593 | M20: =IF(L20<TODAY(),"ATRASO","EM PRODUÇÃO") -> ATRASO | N20: 45593 | O20: OK | P20: OK | Q20: OK | R20: OK | S20: OK | T20: 1215 | U20: ENTREGUE
A21: DANIELE | B21: 45579 | C21: HAVANNA | D21: 1033 | E21: ZF ALIMENTOS (HAVANNA MARILIA) | F21: CAMISETA GOLA CARECA MALHA 100% ALGODÃO | G21: CAMISETA | H21: LEVE | I21: 3 | J21: 36.75 | K21: =I21*J21 -> 110.25 | L21: 45593 | M21: =IF(L21<TODAY(),"ATRASO","EM PRODUÇÃO") -> ATRASO | N21: 45593 | O21: OK | P21: OK | Q21: OK | R21: OK | S21: OK | T21: 1215 | U21: ENTREGUE
A22: DANIELE | B22: 45579 | C22: HAVANNA | D22: 1033 | E22: ZF ALIMENTOS (HAVANNA MARILIA) | F22: CALÇA LEGGIN SUPLEX | G22: CALÇA | H22: LEVE | I22: 12 | J22: 65 | K22: =I22*J22 -> 780 | L22: 45593 | M22: =IF(L22<TODAY(),"ATRASO","EM PRODUÇÃO") -> ATRASO | N22: 45593 | O22: OK | P22: OK | Q22: OK | R22: OK | S22: OK | T22: 1215 | U22: ENTREGUE
A23: DANIELE | B23: 45579 | C23: HAVANNA | D23: 1033 | E23: ZF ALIMENTOS (HAVANNA MARILIA) | F23: FAIXA PARA CABELO TORCIDA | G23: FAIXA | H23: LEVE | I23: 10 | J23: 21 | K23: =I23*J23 -> 210 | L23: 45593 | M23: =IF(L23<TODAY(),"ATRASO","EM PRODUÇÃO") -> ATRASO | N23: 45593 | O23: OK | P23: OK | Q23: OK | R23: OK | S23: OK | T23: 1215 | U23: ENTREGUE
A24: DANIELE | B24: 45579 | C24: HAVANNA | D24: 1033 | E24: ZF ALIMENTOS (HAVANNA MARILIA) | F24: AVENTAL OXFORD MODELO PADRÃO | G24: AVENTAL | H24: LEVE | I24: 10 | J24: 21 | K24: =I24*J24 -> 210 | L24: 45593 | M24: =IF(L24<TODAY(),"ATRASO","EM PRODUÇÃO") -> ATRASO | N24: 45593 | O24: OK | P24: OK | Q24: OK | R24: OK | S24: OK | T24: 1215 | U24: ENTREGUE
A25: LETICIA | B25: 45555 | C25: HAVANNA | D25: 1015 | E25: DOCES E DOCES (HAVANNA PRAIA DE BELLAS) | F25: CAMISETA MALHA 100% ALGODÃO MANGA LONGA | G25: CAMISETA | H25: LEVE | I25: 25 | J25: 45 | K25: =I25*J25 -> 1125 | L25: 45593 | M25: =IF(L25<TODAY(),"ATRASO","EM PRODUÇÃO") -> ATRASO | O25: OK | P25: OK | Q25: OK | R25: OK | S25: OK | T25: OK | U25: ENTREGUE
A26: LETICIA | B26: 45555 | C26: HAVANNA | D26: 1015 | E26: DOCES E DOCES (HAVANNA PRAIA DE BELLAS) | F26: FAIXA PARA CABELO TORCIDA | G26: FAIXA | H26: LEVE | I26: 10 | J26: 21 | K26: =I26*J26 -> 210 | L26: 45593 | M26: =IF(L26<TODAY(),"ATRASO","EM PRODUÇÃO") -> ATRASO | O26: OK | P26: OK | Q26: OK | R26: OK | S26: OK | T26: OK | U26: ENTREGUE
A27: LETICIA | B27: 45560 | C27: PET | D27: 188 | E27: BAMBU BRASIL(ESSENCIA PET) | F27: AVENTAL PET NY IMPERMEAVEL COM VIES | G27: AVENTAL | H27: LEVE | I27: 150 | J27: 23.5 | K27: =I27*J27 -> 3525 | L27: 45583 | M27: =IF(L27<TODAY(),"ATRASO","EM PRODUÇÃO") -> ATRASO | N27: 45588 | O27: OK | P27: OK | Q27: OK | R27: OK | S27: OK | T27: OK | U27: ENTREGUE
A28: LETICIA | B28: 45555 | C28: HAVANNA | D28: 1015 | E28: DOCES E DOCES (HAVANNA PRAIA DE BELLAS) | F28: AVENTAL OXFORD MODELO PADRÃO | G28: AVENTAL | H28: LEVE | I28: 10 | J28: 21 | K28: =I28*J28 -> 210 | L28: 45593 | M28: =IF(L28<TODAY(),"ATRASO","EM PRODUÇÃO") -> ATRASO | O28: OK | P28: OK | Q28: OK | R28: OK | S28: OK | T28: OK | U28: ENTREGUE
A29: DANIELE | B29: 45569 | C29: HAVANNA | D29: 1028 | E29: DRL CAFETERIA (HAVANNA INDAIATUBA) | F29: AVENTAL OXFORD MODELO PADRÃO | G29: AVENTAL | H29: LEVE | I29: 7 | J29: 21 | K29: =I29*J29 -> 147 | L29: 45593 | M29: =IF(L29<TODAY(),"ATRASO","EM PRODUÇÃO") -> ATRASO | O29: OK | P29: OK | Q29: OK | R29: OK | S29: OK | T29: OK | U29: ENTREGUE
A30: DANIELE | B30: 45569 | C30: HAVANNA | D30: 1028 | E30: DRL CAFETERIA (HAVANNA INDAIATUBA) | F30: CAMISETA GOLA CARECA MALHA 100% ALGODÃO | G30: CAMISETA | H30: LEVE | I30: 6 | J30: 41.75 | K30: =I30*J30 -> 250.5 | L30: 45593 | M30: =IF(L30<TODAY(),"ATRASO","EM PRODUÇÃO") -> ATRASO | O30: OK | P30: OK | Q30: OK | R30: OK | S30: OK | T30: OK | U30: ENTREGUE
A31: DANIELE | B31: 45569 | C31: HAVANNA | D31: 1028 | E31: DRL CAFETERIA (HAVANNA INDAIATUBA) | F31: CAMISETA GOLA CARECA MALHA 100% ALGODÃO | G31: CAMISETA | H31: LEVE | I31: 4 | J31: 36.75 | K31: =I31*J31 -> 147 | L31: 45593 | M31: =IF(L31<TODAY(),"ATRASO","EM PRODUÇÃO") -> ATRASO | O31: OK | P31: OK | Q31: OK | R31: OK | S31: OK | T31: OK | U31: ENTREGUE
A32: DANIELE | B32: 45569 | C32: HAVANNA | D32: 1028 | E32: DRL CAFETERIA (HAVANNA INDAIATUBA) | F32: FAIXA PARA CABELO TORCIDA | G32: FAIXA | H32: LEVE | I32: 6 | J32: 21 | K32: =I32*J32 -> 126 | L32: 45593 | M32: =IF(L32<TODAY(),"ATRASO","EM PRODUÇÃO") -> ATRASO | O32: OK | P32: OK | Q32: OK | R32: OK | S32: OK | T32: OK | U32: ENTREGUE
A33: DANIELE | B33: 45589 | C33: HAVANNA | D33: 1022 | E33: JL COMERCIO DE ALIMENTOS (HAVANNA) | F33: FAIXA PARA CABELO TORCIDA | G33: FAIXA | H33: LEVE | I33: 12 | J33: 21 | K33: =I33*J33 -> 252 | L33: 45593 | M33: =IF(L33<TODAY(),"ATRASO","EM PRODUÇÃO") -> ATRASO | N33: 45594 | O33: OK | P33: OK | Q33: OK | R33: OK | S33: OK | T33: 1219 | U33: ENTREGUE
A34: DANIELE | B34: 45589 | C34: HAVANNA | D34: 1022 | E34: JL COMERCIO DE ALIMENTOS (HAVANNA) | F34: CAMISETA FEMININA MALHA 100% ALGODÃO MANGA LONGA | G34: CAMISETA | H34: LEVE | I34: =4+2+2+2 -> 10 | J34: 47.5 | K34: =I34*J34 -> 475 | L34: 45593 | M34: =IF(L34<TODAY(),"ATRASO","EM PRODUÇÃO") -> ATRASO | N34: 45594 | O34: OK | P34: OK | Q34: OK | R34: OK | S34: OK | T34: 1219 | U34: ENTREGUE
A35: DANIELE | B35: 45589 | C35: HAVANNA | D35: 1022 | E35: JL COMERCIO DE ALIMENTOS (HAVANNA) | F35: CAMISETA GOLA CARECA 100% ALGODÃO | G35: CAMISETA | H35: LEVE | I35: =2+2+2 -> 6 | J35: 36.75 | K35: =I35*J35 -> 220.5 | L35: 45593 | M35: =IF(L35<TODAY(),"ATRASO","EM PRODUÇÃO") -> ATRASO | N35: 45594 | O35: OK | P35: OK | Q35: OK | R35: OK | S35: OK | T35: 1219 | U35: ENTREGUE
A36: DANIELE | B36: 45589 | C36: HAVANNA | D36: 1022 | E36: JL COMERCIO DE ALIMENTOS (HAVANNA) | F36: BABY LOOK FEMININA MALHA 100% ALGODÃO | G36: CAMISETA | H36: LEVE | I36: =3+3+3+2 -> 11 | J36: 36.75 | K36: =I36*J36 -> 404.25 | L36: 45593 | M36: =IF(L36<TODAY(),"ATRASO","EM PRODUÇÃO") -> ATRASO | N36: 45594 | O36: OK | P36: OK | Q36: OK | R36: OK | S36: OK | T36: 1219 | U36: ENTREGUE
A37: DANIELE | B37: 45589 | C37: HAVANNA | D37: 1022 | E37: JL COMERCIO DE ALIMENTOS (HAVANNA) | F37: AVENTAL OXFORD MODELO PADRÃO | G37: AVENTAL | H37: LEVE | I37: 13 | J37: 21 | K37: =I37*J37 -> 273 | L37: 45593 | M37: =IF(L37<TODAY(),"ATRASO","EM PRODUÇÃO") -> ATRASO | N37: 45594 | O37: OK | P37: OK | Q37: OK | R37: OK | S37: OK | T37: 1219 | U37: ENTREGUE
A38: LETICIA | B38: 45573 | C38: COSMÉTICO | D38: 617 | E38: M.D BOSO PROHALL | F38: KIMONO CETIM - TAM ÚNICO | G38: KIMONO | H38: LEVE | I38: 400 | J38: 24.5 | K38: =I38*J38 -> 9800 | L38: 45595 | M38: =IF(L38<TODAY(),"ATRASO","EM PRODUÇÃO") -> ATRASO | N38: 45607 | O38: OK | P38: OK | Q38: OK | R38: OK | S38: OK | T38: 967 | U38: ENTREGUE
A39: LETICIA | B39: 45574 | C39: COSMÉTICO | D39: 621 | E39: KOOSMETICS (EXO) | F39: NECESSSAIRE CRISTAL 30A X 16L X 10 - EXO | G39: NECESSAIRE | H39: PESADA | I39: 500 | J39: 7.8 | K39: =I39*J39 -> 3900 | L39: 45595 | M39: =IF(L39<TODAY(),"ATRASO","EM PRODUÇÃO") -> ATRASO | N39: 45594 | O39: OK | P39: OK | Q39: OK | R39: OK | S39: OK | T39: 964 | U39: ENTREGUE
A40: LETICIA | B40: 45573 | C40: COSMÉTICO | D40: 617 | E40: M.D BOSO PROHALL | F40: AVENTAL OXFORD MODELO PADRÃO | G40: AVENTAL | H40: LEVE | I40: =400+300 -> 700 | J40: 14 | K40: =I40*J40 -> 9800 | L40: 45595 | M40: =IF(L40<TODAY(),"ATRASO","EM PRODUÇÃO") -> ATRASO | N40: 45607 | O40: OK | P40: OK | Q40: OK | R40: OK | S40: OK | T40: 967 | U40: ENTREGUE
...

Sheet Planilha2
A1: VENDEDOR | B1: DATA DE ENTRADA | C1: GRUPO DE CLIENTE | D1: PEDIDO | E1: CLIENTE | F1: PRODUTO | G1: GRUPO | H1: LINHA | I1: QUANTIDADE | J1: PREÇO UNITARIO | K1: TOTAL | L1: DATA DE ENTREGA | M1: CORTE | N1: SILK | O1: COSTURA | P1: EMBALAGEM | Q1: TOTAL MO
A2: LETICIA | B2: 45552 | C2: PET | D2: 176 | E2: PETCO CLEAN & CARE (PETCO) | F2: CAMISETA POLO MALHA PIQUET | G2: CAMISETA | H2: LEVE | I2: 10 | J2: 75 | K2: 750 | L2: 45580 | M2: =I2*0.25 -> 2.5 | O2: =I2*7 -> 70 | P2: =I2*0.5 -> 5 | Q2: =M2+N2+O2+P2 -> 77.5
A3: LETICIA | B3: 45552 | C3: PET | D3: 177 | E3: PETCO CLEAN & CARE (PETCO) | F3: JALECO MICROFIBRA COM TAFETA- PETCO | G3: JALECO | H3: LEVE | I3: 210 | J3: 55 | K3: 11550 | L3: 45580 | M3: =I3*0.25 -> 52.5 | N3: =I3*2 -> 420 | O3: =I3*10 -> 2100 | P3: =I3*0.5 -> 105 | Q3: =M3+N3+O3+P3 -> 2677.5
A4: LETICIA | B4: 45553 | C4: PET | D4: 181 | E4: CHEMVET (PETSPA) | F4: JALECO MICROFIBRA COM TAFETA- PETSPA | G4: JALECO | H4: LEVE | I4: 200 | J4: 55 | K4: 11000 | L4: 45581 | M4: =I4*0.25 -> 50 | N4: =I4*2 -> 400 | O4: =I4*10 -> 2000 | P4: =I4*0.5 -> 100 | Q4: =M4+N4+O4+P4 -> 2550
A5: LETICIA | B5: 45560 | C5: COSMÉTICO | D5: 187 | E5: DUO INDUSTRIA (KPRO) | F5: AVENTAL GABARDINE MODELO PADRÃO | G5: AVENTAL | H5: LEVE | I5: 500 | J5: 19.5 | K5: 9750 | L5: 45588 | M5: =I5*0.25 -> 125 | N5: =I5*0.7 -> 350 | O5: =I5*1.2 -> 600 | P5: =I5*0.5 -> 250 | Q5: =M5+N5+O5+P5 -> 1325
A6: LETICIA | B6: 45572 | C6: COSMÉTICO | D6: 616 | E6: FLORA DISTRIBUIDORA | F6: CAMISETA MALHA PV GOLA CARECA | G6: CAMISETA | H6: LEVE | I6: 112 | J6: 26.5 | K6: 2968 | L6: 45586 | M6: =I6*0.25 -> 28 | N6: =I6*1.5 -> 168 | O6: =I6*1.5 -> 168 | P6: =I6*0.5 -> 56 | Q6: =M6+N6+O6+P6 -> 420
A7: LETICIA | B7: 45581 | C7: COSMÉTICO | D7: 198 | E7: DUO INDUSTRIA (KPRO) | F7: AVENTAL NY EMBORRACHADO 5 BOLSOS | G7: AVENTAL | H7: LEVE | I7: 300 | J7: 19.2 | K7: 5760 | L7: 45609 | M7: =I7*0.25 -> 75 | N7: =I7*0.7 -> 210 | O7: =I7*1.3 -> 390 | P7: =I7*0.5 -> 150 | Q7: =M7+N7+O7+P7 -> 825
A8: LETICIA | B8: 45574 | C8: COSMÉTICO | D8: 619 | E8: M.D BOSO PROHALL | F8: CAMISETA GOLA CARECA MALHA PV | G8: CAMISETA | H8: LEVE | I8: 34 | J8: 24.5 | K8: 833 | L8: 45590 | M8: =I8*0.25 -> 8.5 | N8: =I8*1.5 -> 51 | O8: =I8*1.5 -> 51 | P8: =I8*0.5 -> 17 | Q8: =M8+N8+O8+P8 -> 127.5
A9: LETICIA | B9: 45572 | C9: PET | D9: 1029 | E9: PET SOCIETY | F9: AVENTAL NYLON EMBORRACHADO CA 45.305-HYDRA | G9: AVENTAL | H9: LEVE | I9: 2500 | J9: 23.5 | K9: 58750 | L9: 45601 | M9: =I9*0.25 -> 625 | N9: =I9*1 -> 2500 | O9: =I9*1.65 -> 4125 | P9: =I9*0.5 -> 1250 | Q9: =M9+N9+O9+P9 -> 8500
A10: DANIELE | B10: 45579 | C10: HAVANNA | D10: 1033 | E10: ZF ALIMENTOS (HAVANNA MARILIA) | F10: BABY LOOK FEMININA MALHA 100% ALGODÃO | G10: CAMISETA | H10: LEVE | I10: 11 | J10: 36.75 | K10: 404.25 | L10: 45593 | M10: =I10*0.25 -> 2.75 | N10: =I10*1.5 -> 16.5 | O10: =I10*1.5 -> 16.5 | P10: =I10*0.5 -> 5.5 | Q10: =M10+N10+O10+P10 -> 41.25
A11: LETICIA | B11: 45572 | C11: PET | D11: 615 | E11: ECO COSMETICOS | F11: AVENTAL NYLON EMBORRACHADO COR VERDE | G11: AVENTAL | H11: LEVE | I11: 150 | J11: 23 | K11: 3450 | L11: 45600 | M11: =I11*0.25 -> 37.5 | N11: =I11*1 -> 150 | O11: =I11*1 -> 150 | P11: =I11*0.5 -> 75 | Q11: =M11+N11+O11+P11 -> 412.5
A12: DANIELE | B12: 45589 | C12: HAVANNA | D12: 1022 | E12: JL COMERCIO DE ALIMENTOS (HAVANNA) | F12: BABY LOOK FEMININA MALHA 100% ALGODÃO | G12: CAMISETA | H12: LEVE | I12: 11 | J12: 36.75 | K12: 404.25 | L12: 45593 | M12: =I12*0.25 -> 2.75 | N12: =I12*1.5 -> 16.5 | O12: =I12*1.5 -> 16.5 | P12: =I12*0.5 -> 5.5 | Q12: =M12+N12+O12+P12 -> 41.25
A13: DANIELE | B13: 45579 | C13: HAVANNA | D13: 1033 | E13: ZF ALIMENTOS (HAVANNA MARILIA) | F13: CALÇA LEGGIN SUPLEX | G13: CALÇA | H13: LEVE | I13: 12 | J13: 65 | K13: 780 | L13: 45593 | M13: =I13*0.25 -> 3 | O13: =I13*3 -> 36 | P13: =I13*0.5 -> 6 | Q13: =M13+N13+O13+P13 -> 45
A14: DANIELE | B14: 45566 | C14: COSMÉTICO | D14: 190 | E14: FILO COSMETICOS | F14: AVENTAL OXFORD MODELO PADRÃO | G14: AVENTAL | H14: LEVE | I14: 100 | J14: 17 | K14: 1700 | L14: 45594 | M14: =I14*0.25 -> 25 | N14: =I14*0.7 -> 70 | O14: =I14*1.5 -> 150 | P14: =I14*0.5 -> 50 | Q14: =M14+N14+O14+P14 -> 295
A15: LETICIA | B15: 45579 | C15: INDUSTRIA | D15: 1041 | E15: NESTING | F15: ETIQUETA ALGODÃO CRU | G15: ETIQUETA | H15: LEVE | I15: 500 | J15: 2.5 | K15: 1250 | L15: 45607 | M15: =I15*0.25 -> 125 | N15: =I15*0.3 -> 150 | O15: =I15*0.15 -> 75 | P15: =I15*0.5 -> 250 | Q15: =M15+N15+O15+P15 -> 600
A16: LETICIA | B16: 45569 | C16: COSMÉTICO | D16: 613 | E16: FLORACTIVE | F16: CAMISETA GOLA CARECA MALHA PV | G16: CAMISETA | H16: LEVE | I16: 100 | J16: 16.5 | K16: 1650 | L16: 45595 | M16: =I16*0.25 -> 25 | N16: =I16*1.5 -> 150 | O16: =I16*1.5 -> 150 | P16: =I16*0.5 -> 50 | Q16: =M16+N16+O16+P16 -> 375
A17: LETICIA | B17: 45573 | C17: COSMÉTICO | D17: 617 | E17: M.D BOSO PROHALL | F17: AVENTAL OXFORD MODELO PADRÃO | G17: AVENTAL | H17: LEVE | I17: 700 | J17: 14 | K17: 9800 | L17: 45595 | M17: =I17*0.25 -> 175 | N17: =I17*0.7 -> 490 | O17: =I17*1.5 -> 1050 | P17: =I17*0.5 -> 350 | Q17: =M17+N17+O17+P17 -> 2065
A18: LETICIA | B18: 45582 | C18: COSMÉTICO | D18: 623 | E18: HRT COSMETICOS (MERLOT) | F18: AVENTAL OXFORD MODELO PADRÃO | G18: AVENTAL | H18: LEVE | I18: 100 | J18: 17.5 | K18: 1750 | L18: 45610 | M18: =I18*0.25 -> 25 | N18: =I18*0.7 -> 70 | O18: =I18*1.5 -> 150 | P18: =I18*0.5 -> 50 | Q18: =M18+N18+O18+P18 -> 295
A19: DANIELE | B19: 45579 | C19: HAVANNA | D19: 1033 | E19: ZF ALIMENTOS (HAVANNA MARILIA) | F19: FAIXA PARA CABELO TORCIDA | G19: FAIXA | H19: LEVE | I19: 10 | J19: 21 | K19: 210 | L19: 45593 | M19: =I19*0.25 -> 2.5 | N19: =I19*0.5 -> 5 | O19: =I19*0.75 -> 7.5 | P19: =I19*0.5 -> 5 | Q19: =M19+N19+O19+P19 -> 20
A20: LETICIA | B20: 45574 | C20: COSMÉTICO | D20: 620 | E20: EAE COSMETICOS | F20: CAMISETA GOLA CARECA MALHA PV | G20: CAMISETA | H20: LEVE | I20: 160 | J20: 35 | K20: 5600 | L20: 45602 | M20: =I20*0.25 -> 40 | N20: =I20*1.5 -> 240 | O20: =I20*1.5 -> 240 | P20: =I20*0.5 -> 80 | Q20: =M20+N20+O20+P20 -> 600
A21: LETICIA | B21: 45574 | C21: INDUSTRIA | D21: 192 | E21: GIRARDI CONFECCAO | F21: CAMISETA GOLA CARECA MALHA PV | G21: CAMISETA | H21: LEVE | I21: 80 | J21: 26.5 | K21: 2120 | L21: 45602 | M21: =I21*0.25 -> 20 | N21: =I21*1.5 -> 120 | O21: =I21*1.5 -> 120 | P21: =I21*0.5 -> 40 | Q21: =M21+N21+O21+P21 -> 300
A22: LETICIA | B22: 45574 | C22: INDUSTRIA | D22: 193 | E22: GIRARDI CONFECCAO | F22: CAMISETA GOLA CARECA MALHA PV | G22: CAMISETA | H22: LEVE | I22: 80 | J22: 26.5 | K22: 2120 | L22: 45603 | M22: =I22*0.25 -> 20 | N22: =I22*1.5 -> 120 | O22: =I22*1.5 -> 120 | P22: =I22*0.5 -> 40 | Q22: =M22+N22+O22+P22 -> 300
A23: DANIELE | B23: 45579 | C23: HAVANNA | D23: 1033 | E23: ZF ALIMENTOS (HAVANNA MARILIA) | F23: AVENTAL OXFORD MODELO PADRÃO | G23: AVENTAL | H23: LEVE | I23: 10 | J23: 21 | K23: 210 | L23: 45593 | M23: =I23*0.25 -> 2.5 | N23: =I23*0.7 -> 7 | O23: =I23*1.5 -> 15 | P23: =I23*0.5 -> 5 | Q23: =M23+N23+O23+P23 -> 29.5
A24: LETICIA | B24: 45579 | C24: BARBEARIA | D24: 197 | E24: DONA NAVALHA BARBEARIA | F24: CAPA DE CORTE TACTEL | G24: CAPA | H24: LEVE | I24: 20 | J24: 80 | K24: 1600 | L24: 45604 | M24: =I24*0.25 -> 5 | N24: =I24*1.5 -> 30 | O24: =I24*2 -> 40 | P24: =I24*0.5 -> 10 | Q24: =M24+N24+O24+P24 -> 85
A25: LETICIA | B25: 45555 | C25: HAVANNA | D25: 1015 | E25: DOCES E DOCES (HAVANNA PRAIA DE BELLAS) | F25: FAIXA PARA CABELO TORCIDA | G25: FAIXA | H25: LEVE | I25: 10 | J25: 21 | K25: 210 | L25: 45593 | M25: =I25*0.25 -> 2.5 | N25: =I25*0.5 -> 5 | O25: =I25*0.75 -> 7.5 | P25: =I25*0.5 -> 5 | Q25: =M25+N25+O25+P25 -> 20
A26: LETICIA | B26: 45580 | C26: INDUSTRIA | D26: 1034 | E26: PLATOLANDIA | F26: CAMISETA GOLA CARECA 100% ALGODÃO | G26: CAMISETA | H26: LEVE | I26: 200 | J26: 26.19 | K26: 5238 | L26: 45608 | M26: =I26*0.25 -> 50 | N26: =I26*1.5 -> 300 | O26: =I26*1.5 -> 300 | P26: =I26*0.5 -> 100 | Q26: =M26+N26+O26+P26 -> 750
A27: LETICIA | B27: 45555 | C27: HAVANNA | D27: 1015 | E27: DOCES E DOCES (HAVANNA PRAIA DE BELLAS) | F27: AVENTAL OXFORD MODELO PADRÃO | G27: AVENTAL | H27: LEVE | I27: 10 | J27: 21 | K27: 210 | L27: 45593 | M27: =I27*0.25 -> 2.5 | N27: =I27*0.7 -> 7 | O27: =I27*1.5 -> 15 | P27: =I27*0.5 -> 5 | Q27: =M27+N27+O27+P27 -> 29.5
A28: DANIELE | B28: 45569 | C28: HAVANNA | D28: 1028 | E28: DRL CAFETERIA (HAVANNA INDAIATUBA) | F28: AVENTAL OXFORD MODELO PADRÃO | G28: AVENTAL | H28: LEVE | I28: 7 | J28: 21 | K28: 147 | L28: 45593 | M28: =I28*0.25 -> 1.75 | N28: =I28*0.7 -> 4.9 | O28: =I28*1.5 -> 10.5 | P28: =I28*0.5 -> 3.5 | Q28: =M28+N28+O28+P28 -> 20.65
A29: LETICIA | B29: 45582 | C29: COSMÉTICO | D29: 623 | E29: HRT COSMETICOS (MERLOT) | F29: CAPA DE CORTE CETIM 0,85 X 1,40 | G29: CAPA | H29: LEVE | I29: 100 | J29: 18.5 | K29: 1850 | L29: 45610 | M29: =I29*0.25 -> 25 | N29: =I29*1.5 -> 150 | O29: =I29*2 -> 200 | P29: =I29*0.5 -> 50 | Q29: =M29+N29+O29+P29 -> 425
A30: LETICIA | B30: 45555 | C30: HAVANNA | D30: 1015 | E30: DOCES E DOCES (HAVANNA PRAIA DE BELLAS) | F30: CAMISETA GOLA CARECA MALHA 100% ALGODÃO | G30: CAMISETA | H30: LEVE | I30: 45 | J30: 36.75 | K30: 1653.75 | L30: 45593 | M30: =I30*0.25 -> 11.25 | N30: =I30*1.5 -> 67.5 | O30: =I30*1.5 -> 67.5 | P30: =I30*0.5 -> 22.5 | Q30: =M30+N30+O30+P30 -> 168.75
A31: LETICIA | B31: 45555 | C31: HAVANNA | D31: 1015 | E31: DOCES E DOCES (HAVANNA PRAIA DE BELLAS) | F31: CAMISETA FEMININA MALHA 100% ALGODÃO MANGA LONGA | G31: CAMISETA | H31: LEVE | I31: 45 | J31: 45 | K31: 2025 | L31: 45593 | M31: =I31*0.25 -> 11.25 | N31: =I31*1.5 -> 67.5 | O31: =I31*1.5 -> 67.5 | P31: =I31*0.5 -> 22.5 | Q31: =M31+N31+O31+P31 -> 168.75
A32: DANIELE | B32: 45569 | C32: HAVANNA | D32: 1028 | E32: DRL CAFETERIA (HAVANNA INDAIATUBA) | F32: FAIXA PARA CABELO TORCIDA | G32: FAIXA | H32: LEVE | I32: 6 | J32: 21 | K32: 126 | L32: 45593 | M32: =I32*0.25 -> 1.5 | N32: =I32*0.5 -> 3 | O32: =I32*0.75 -> 4.5 | P32: =I32*0.5 -> 3 | Q32: =M32+N32+O32+P32 -> 12
A33: DANIELE | B33: 45579 | C33: HAVANNA | D33: 1033 | E33: ZF ALIMENTOS (HAVANNA MARILIA) | F33: CAMISETA FEMININA MALHA 100% ALGODÃO MANGA LONGA | G33: CAMISETA | H33: LEVE | I33: 8 | J33: 47.5 | K33: 380 | L33: 45593 | M33: =I33*0.25 -> 2 | N33: =I33*1.5 -> 12 | O33: =I33*1.5 -> 12 | P33: =I33*0.5 -> 4 | Q33: =M33+N33+O33+P33 -> 30
A34: DANIELE | B34: 45579 | C34: HAVANNA | D34: 1033 | E34: ZF ALIMENTOS (HAVANNA MARILIA) | F34: CAMISETA GOLA CARECA MALHA 100% ALGODÃO | G34: CAMISETA | H34: LEVE | I34: 3 | J34: 36.75 | K34: 110.25 | L34: 45593 | M34: =I34*0.25 -> 0.75 | N34: =I34*1.5 -> 4.5 | O34: =I34*1.5 -> 4.5 | P34: =I34*0.5 -> 1.5 | Q34: =M34+N34+O34+P34 -> 11.25
A35: DANIELE | B35: 45589 | C35: HAVANNA | D35: 1022 | E35: JL COMERCIO DE ALIMENTOS (HAVANNA) | F35: FAIXA PARA CABELO TORCIDA | G35: FAIXA | H35: LEVE | I35: 12 | J35: 21 | K35: 252 | L35: 45593 | M35: =I35*0.25 -> 3 | N35: =I35*0.5 -> 6 | O35: =I35*0.75 -> 9 | P35: =I35*0.5 -> 6 | Q35: =M35+N35+O35+P35 -> 24
A36: LETICIA | B36: 45573 | C36: COSMÉTICO | D36: 617 | E36: M.D BOSO PROHALL | F36: KIMONO CETIM - TAM ÚNICO | G36: KIMONO | H36: LEVE | I36: 400 | J36: 24.5 | K36: 9800 | L36: 45595 | M36: =I36*0.25 -> 100 | N36: =I36*1.5 -> 600 | O36: =I36*10 -> 4000 | P36: =I36*0.5 -> 200 | Q36: =M36+N36+O36+P36 -> 4900
A37: DANIELE | B37: 45589 | C37: HAVANNA | D37: 1022 | E37: JL COMERCIO DE ALIMENTOS (HAVANNA) | F37: AVENTAL OXFORD MODELO PADRÃO | G37: AVENTAL | H37: LEVE | I37: 13 | J37: 21 | K37: 273 | L37: 45593 | M37: =I37*0.25 -> 3.25 | N37: =I37*0.7 -> 9.1 | O37: =I37*1.5 -> 19.5 | P37: =I37*0.5 -> 6.5 | Q37: =M37+N37+O37+P37 -> 38.35
A38: LETICIA | B38: 45555 | C38: HAVANNA | D38: 1015 | E38: DOCES E DOCES (HAVANNA PRAIA DE BELLAS) | F38: CAMISETA MALHA 100% ALGODÃO MANGA LONGA | G38: CAMISETA | H38: LEVE | I38: 25 | J38: 45 | K38: 1125 | L38: 45593 | M38: =I38*0.25 -> 6.25 | N38: =I38*1.5 -> 37.5 | O38: =I38*1.5 -> 37.5 | P38: =I38*0.5 -> 12.5 | Q38: =M38+N38+O38+P38 -> 93.75
A39: DANIELE | B39: 45566 | C39: COSMÉTICO | D39: 190 | E39: FILO COSMETICOS | F39: NECESSAIRE CRISTAL COM VIES | G39: NECESSAIRE | H39: PESADA | I39: 100 | J39: 12 | K39: 1200 | L39: 45594 | M39: =I39*0.25 -> 25 | N39: =I39*0.5 -> 50 | O39: =I39*1.8 -> 180 | P39: =I39*0.5 -> 50 | Q39: =M39+N39+O39+P39 -> 305
A40: DANIELE | B40: 45540 | C40: PET | D40: 194 | E40: MANU PET STORE | F40: AVENTAL PET NY IMPERMEAVEL COM VIES | G40: AVENTAL | H40: LEVE | I40: 100 | J40: 27 | K40: 2700 | L40: 45603 | M40: =I40*0.25 -> 25 | N40: =I40*0.7 -> 70 | O40: =I40*1.5 -> 150 | P40: =I40*0.5 -> 50 | Q40: =M40+N40+O40+P40 -> 295
...

Sheet TOTAIS (PLANILHA INATIVA)
B2: CARTEIRA EM PRODUÇÃO | F2: TOTAIS EM CARTEIRA POR GRUPO | L2: CUSTO MÃO DE OBRA
B3: PEÇAS | C3: FATURAR | D3: LIQUIDAR | F3: GRUPO | G3: QTD | H3: FATURAR | I3: LIQUIDAR | L3: EM PRODUÇÃO
B4: ='PCP + MO '!J1629 -> 24489 | C4: ='PCP + MO '!L1629 -> 419654.5 | D4: ='PCP + MO '!M1629 -> 246959.5 | F4: Avental | G4: 5160 | H4: 114359 | I4: 93172.5 | L4: CORTE | M4: ='PCP + MO '!R1629 -> 0
F5: Camiseta | G5: 1863 | H5: 47509.5 | I5: 29076.62 | L5: SILK | M5: ='PCP + MO '!S1629 -> 0
F6: Necessaire | G6: 2000 | H6: 18620 | I6: 10810 | L6: COSTURA | M6: ='PCP + MO '!T1629 -> 0
F7: Capa Protetor | G7: 1500 | H7: 24000 | I7: 24000 | L7: EMBALAGEM | M7: ='PCP + MO '!U1629 -> 0
F8: Kimono | G8: 1190 | H8: 30075 | I8: 27400 | L8: TOTAL | M8: =SUM(M4:M7) -> 0
F9: Capa de Corte | G9: 865 | H9: 19575 | I9: 16262.5
F10: Saco | G10: 400 | H10: 9800 | I10: 9800
F11: Polo | G11: 170 | H11: 8280 | I11: 270
F12: Sacola | G12: 100 | H12: 3500 | I12: 0
F13: Touca | G13: 100 | H13: 1100 | I13: 1100
F14: Etiqueta | G14: 500 | H14: 1250 | I14: 1250
F15: Calça Brim | G15: 25 | H15: 1875 | I15: 1875
F16: Faixa | G16: 44 | H16: 1044 | I16: 960
F17: Moleton | G17: 7 | H17: 595 | I17: 0
F18: Calça Leggin | G18: 1 | H18: 65 | I18: 32.5
F19: TOTAL | G19: =SUM(G4:G18) -> 13925 | H19: =SUM(H4:H18) -> 281647.5 | I19: =SUM(I4:I18) -> 216009.12
F20: Ticket Médio | I20: =H19/G19 -> 20.226032
F21: Margem de Recebimento Antecipado | I21: =100%-I19/H19 -> 0.23305153

Sheet VENDAS (PLANILHA INATIVA)
B2: CARTEIRA EM PRODUÇÃO
B3: Peças
B4: Valores
B6: VENDAS
B7: MÊS | C7: PEDIDOS | D7: ITENS | E7: VALORES
B8: ABRIL | C8: 42 | D8: 19516 | E8: 397092.25
B9: MAIO | C9: 40 | D9: 31359 | E9: 575422.5
B10: JUNHO | C10: 51 | D10: 12014 | E10: 283366.5
B11: JULHO | C11: 42 | D11: 10970 | E11: 221481.5
B12: AGOSTO | C12: =C26 -> 49 | D12: =D26 -> 17849 | E12: =E26 -> 244599.75
B13: SETEMBRO | C13: =C27 -> 43 | D13: =D27 -> 13011 | E13: =E27 -> 279023.5
B14: OUTUBRO | C14: 62 | D14: 18150 | E14: 370963
B15: NOVEMBRO | C15: 48 | D15: 15392 | E15: 255680.25
B16: DEZEMBRO | C16: 19 | D16: 7394 | E16: 151501.5
B17: TOTAL | C17: =SUM(C8:C16) -> 396 | D17: =SUM(D8:D16) -> 145655 | E17: =SUM(E8:E16) -> 2779130.8
B19: TOTAL REALIZADO | F19: MÉDIA REALIZADA | K19: Mês | L19: Vendido | M19: Faturado | N19: Pago
B20: Mês | C20: Pedidos | D20: Peças Vendidas | E20: Valores de Vendas | F20: Dias Uteis | G20: Média de Pedidos Dia | H20: Média de Peças Dia | I20: Média de Valores Dia | K20: ABRIL | L20: 397092.25 | M20: 255543 | N20: 480901.63
K21: MAIO | L21: 575422.5 | M21: 369011 | N21: 503604.63
B22: ABRIL | C22: 42 | D22: 19516 | E22: 397092.25 | F22: 20 | G22: =C22/F22 -> 2.1 | H22: =D22/F22 -> 975.8 | I22: =E22/F22 -> 19854.612 | K22: JUNHO | L22: 283366.5 | M22: 342831.95 | N22: 296535.04
B23: MAIO | C23: 40 | D23: 31359 | E23: 575422.5 | F23: 21 | G23: =C23/F23 -> 1.9047619 | H23: =D23/F23 -> 1493.2857 | I23: =E23/F23 -> 27401.071 | K23: JULHO | L23: 221481.5 | M23: 576329.75 | N23: 401333.98
B24: JUNHO | C24: 51 | D24: 12014 | E24: 283366.5 | F24: 20 | G24: =C24/F24 -> 2.55 | H24: =D24/F24 -> 600.7 | I24: =E24/F24 -> 14168.325 | K24: AGOSTO | L24: =E26 -> 244599.75 | M24: 330213.95 | N24: 297759.34
B25: JULHO | C25: 42 | D25: 10970 | E25: 221481.5 | F25: 22 | G25: =C25/F25 -> 1.9090909 | H25: =D25/F25 -> 498.63636 | I25: =E25/F25 -> 10067.341 | K25: SETEMBRO | L25: =E27 -> 279023.5 | M25: 216774 | N25: 183954.49
B26: AGOSTO | C26: 49 | D26: 17849 | E26: 244599.75 | F26: 21 | G26: =C26/F26 -> 2.3333333 | H26: =D26/F26 -> 849.95238 | I26: =E26/F26 -> 11647.607 | K26: OUTUBRO | L26: =E28 -> 370963
B27: SETEMBRO | C27: 43 | D27: 13011 | E27: 279023.5 | F27: 21 | G27: =C27/F27 -> 2.047619 | H27: =D27/F27 -> 619.57143 | I27: =E27/F27 -> 13286.833
B28: OUTUBRO | C28: 62 | D28: 18150 | E28: 370963 | F28: 23 | G28: =C28/F28 -> 2.6956522 | H28: =D28/F28 -> 789.13043 | I28: =E28/F28 -> 16128.826
B29: NOVEMBRO | C29: 48 | D29: 15392 | E29: 255680.25 | F29: 20 | G29: =C29/F29 -> 2.4 | H29: =D29/F29 -> 769.6 | I29: =E29/F29 -> 12784.013
B31: TOTAL | C31: =SUM(C22:C29) -> 377 | D31: =SUM(D22:D29) -> 138261 | E31: =SUM(E22:E29) -> 2627629.2 | F31: =AVERAGE(F22:F28) -> 21.142857 | G31: =AVERAGE(G22:G27) -> 2.1408009 | H31: =AVERAGE(H22:H27) -> 839.65765 | I31: =AVERAGE(I22:I27) -> 16070.965
B32: MÉDIA | C32: =AVERAGE(C22:C26) -> 44.8 | D32: =AVERAGE(D22:D26) -> 18341.6 | E32: =AVERAGE(E22:E26) -> 344392.5
B34: Realizado proporcional aos meses anteriores
B35: ABRIL | C35: =E29/E22 -> 0.64388124
B36: MAIO | C36: =E29/E23 -> 0.44433481 | G36: Vendido
B37: JUNHO | C37: =E29/E24 -> 0.90229526 | G37: Faturado
B38: JULHO | C38: =E29/E25 -> 1.1544091 | G38: Pago
B39: AGOSTO | C39: =E29/E26 -> 1.0453005
B40: SETEMBRO | C40: =E29/E27 -> 0.91633948
B41: OUTUBRO
B42: NOVEMBRO
B44: MÊS | C44: Vendido | D44: Faturado
B45: ABRIL | C45: 397092.25 | D45: 255543
B46: MAIO | C46: 575422.5 | D46: 369011
...

Sheet RELATÓRIO HAVANNA
A1: RELATÓRIO DE PEDIDOS HAVANNA
A3: PEDIDO | B3: DATA DO PEDIDO | C3: CLIENTE | D3: PRODUTO | E3: GRUPO | F3: QTD | G3: VALOR UNID | H3: TOTAL
A4: 1101 | B4: 45297 | C4: PATAGONIA CAFÉ LTDA | D4: CAMISETA MALHA 100% ALGODÃO | E4: CAMISETA | F4: 16 | G4: 36.75 | H4: =G4*F4 -> 588
A5: 911 | B5: 45412 | C5: DGA DOCES | D5: SACOLA DE LONITA MODELO HAVANNA | E5: SACOLA | F5: 250 | G5: 16.5 | H5: =G5*F5 -> 4125
A6: 904 | B6: 45419 | C6: DGA DOCES | D6: CAMISETA MALHA 100% ALGODÃO | E6: CAMISETA | F6: 500 | G6: 26.8 | H6: =G6*F6 -> 13400
A7: 912 | B7: 45421 | C7: DGA DOCES | D7: SACOLA SUBLIMADA TECIDO PET | E7: SACOLA | F7: 250 | G7: 19 | H7: =G7*F7 -> 4750
A8: 929 | B8: 45440 | C8: CAFÉ DEL PLATA | D8: CAMISETA MANGA LONGA MALHA 100% ALGODÃO | E8: CAMISETA | F8: 7 | G8: 47.5 | H8: =G8*F8 -> 332.5
A9: 929 | B9: 45440 | C9: CAFÉ DEL PLATA | D9: CAMISETA MALHA 100% ALGODÃO | E9: CAMISETA | F9: 7 | G9: 33.88 | H9: =G9*F9 -> 237.16
A10: 929 | B10: 45440 | C10: CAFÉ DEL PLATA | D10: CAMISETA MALHA 100% ALGODÃO BABY LOOK | E10: CAMISETA | F10: 4 | G10: 33.88 | H10: =G10*F10 -> 135.52
A11: 929 | B11: 45440 | C11: CAFÉ DEL PLATA | D11: CAMISETA MANGA LONGA MALHA 100% ALGODÃO BABY LOOK | E11: CAMISETA | F11: 4 | G11: 47.5 | H11: =G11*F11 -> 190
A12: 928 | B12: 45440 | C12: CAFÉ DEL PLATA | D12: CAMISETA MANGA LONGA MALHA 100% ALGODÃO | E12: CAMISETA | F12: 7 | G12: 47.5 | H12: =G12*F12 -> 332.5
A13: 928 | B13: 45440 | C13: CAFÉ DEL PLATA | D13: CAMISETA MALHA 100% ALGODÃO | E13: CAMISETA | F13: 7 | G13: 33.88 | H13: =G13*F13 -> 237.16
A14: 928 | B14: 45440 | C14: CAFÉ DEL PLATA | D14: CAMISETA MALHA 100% ALGODÃO BABY LOOK | E14: CAMISETA | F14: 4 | G14: 33.88 | H14: =G14*F14 -> 135.52
A15: 928 | B15: 45440 | C15: CAFÉ DEL PLATA | D15: CAMISETA MANGA LONGA MALHA 100% ALGODÃO BABY LOOK | E15: CAMISETA | F15: 4 | G15: 47.5 | H15: =G15*F15 -> 190
... A570: 637 | B570: 46219 | C570: J.A DA CAMARA FERNANDEZ | D570: POLO PIQUET | E570: POLO | F570: 2 | G570: 65 | H570: =G570*F570 -> 130
F574: =SUM(F4:F573) -> 5510 | H574: =SUM(H4:H573) -> 198103.11
F575: Peças | H575: Faturamento

Sheet VENDAS HAVANNA 2026
B1: 2026
B3: VENDAS HAVANNA | C3: MÊS | D3: PEÇAS | E3: VALORES
C4: JANEIRO | D4: 115 | E4: 3533
C5: FEVEREIRO | D5: 48 | E5: 1693.5
C6: MARÇO | D6: 140 | E6: 5267
C7: ABRIL | D7: 53 | E7: 1715
C8: MAIO | D8: 24 | E8: 1354.5
C9: JUNHO | D9: 241 | E9: 9717.5
C10: JULHO
C11: AGOSTO
C12: SETEMBRO
C13: OUTUBRO
C14: NOVEMBRO
C15: DEZEMBRO
C16: TOTAL | D16: =SUM(D4:D15) -> 621 | E16: =SUM(E4:F15) -> 23280.5
B19: VENDAS HAVANNA - QTD PEÇAS | P19: VENDAS HAVANNA - VALORES
B20: ITEM | C20: JAN | D20: FEV | E20: MAR | F20: ABR | G20: MAI | H20: JUN | I20: JUL | J20: AGO | K20: SET | L20: OUT | M20: NOV | N20: TOTAL | P20: ITEM | Q20: JAN | R20: FEV | S20: MAR | T20: ABR | U20: MAIO | V20: JUNHO | W20: JULHO | X20: AGOSTO | Y20: SETEMBRO | Z20: OUTUBRO | AA20: NOVEMBRO | AB20: TOTAL
B21: AVENTAIS | C21: 37 | D21: 13 | E21: 25 | F21: 12 | G21: 1 | H21: 66 | N21: =SUM(C21:M21) -> 154 | P21: AVENTAIS | Q21: =C21*25 -> 925 | R21: =D21*25 -> 325 | S21: =E21*25 -> 625 | T21: =F21*25 -> 300 | AB21: =SUM(Q21:AA21) -> 2175
B22: CAMISETA GOLA CARECA | C22: 48 | D22: 10 | E22: 49 | F22: 24 | G22: 10 | H22: 101 | N22: =SUM(C22:M22) -> 242 | P22: CAMISETA GOLA CARECA | Q22: =C22*36.75 -> 1764 | R22: 432 | S22: =E22*36.75 -> 1800.75 | T22: =F22*36.75 -> 882 | AB22: =SUM(Q22:AA22) -> 4878.75
B23: CAMISETA MANGA LONGA | C23: 8 | D23: 18 | E23: 27 | F23: 0 | H23: 19 | N23: =SUM(C23:L23) -> 72 | P23: CAMISETA MANGA LONGA | Q23: =C23*36.75 -> 294 | R23: =D23*36.75 -> 661.5 | S23: =E23*36.75 -> 992.25 | T23: =F23*36.75 -> 0 | AB23: =SUM(Q23:Z23) -> 1947.75
B24: POLO | C24: 2 | D24: 0 | E24: 6 | F24: 4 | H24: 6 | N24: =SUM(C24:M24) -> 18 | P24: POLO | Q24: =C24*65 -> 130 | R24: =D24*65 -> 0 | S24: =E24*65 -> 390 | T24: =F24*65 -> 260 | AB24: =SUM(Q24:AA24) -> 780
B25: CALÇA | C25: 0 | D25: 0 | E25: 13 | G25: 5 | H25: 3 | N25: =SUM(C25:L25) -> 21 | P25: CALÇA | Q25: =C25*75 -> 0 | R25: =D25*75 -> 0 | S25: =E25*75 -> 975 | T25: =F25*75 -> 0 | AB25: =SUM(Q25:Z25) -> 975
B26: FAIXA P/ CABELO | C26: 20 | D26: 5 | E26: 19 | F26: 13 | G26: 2 | H26: 28 | N26: =SUM(C26:M26) -> 87 | P26: FAIXA P/ CABELO | Q26: =C26*21 -> 420 | R26: =D26*21 -> 105 | S26: =E26*21 -> 399 | T26: =F26*21 -> 273 | AB26: =SUM(Q26:AA26) -> 1197
B27: MOLETOM | C27: 0 | D27: 2 | E27: 1 | G27: 6 | H27: 18 | N27: =SUM(C27:M27) -> 27 | P27: MOLETOM | Q27: =C27*85 -> 0 | R27: =D27*85 -> 170 | S27: =E27*85 -> 85 | T27: =F27*85 -> 0 | AB27: =SUM(Q27:AA27) -> 255
B28: TOTAL | C28: =SUM(C21:C27) -> 115 | D28: =SUM(D21:D27) -> 48 | E28: =SUM(E21:E27) -> 140 | F28: =SUM(F21:F27) -> 53 | G28: =SUM(G21:G27) -> 24 | H28: =SUM(H21:H27) -> 241 | I28: =SUM(I21:I27) -> 0 | J28: =SUM(J21:J27) -> 0 | ... M28: =SUM(M21:M27) -> 0 | N28: =SUM(C28:M28) -> 621 | P28: TOTAL | Q28: =SUM(Q21:Q27) -> 3533 | R28: =SUM(R21:R27) -> 1693.5 | S28: =SUM(S21:S27) -> 5267 | T28: =SUM(T21:T27) -> 1715 | U28: =SUM(U21:U27) -> 0 | V28: =SUM(V21:V27) -> 0 | W28: =SUM(W21:W27) -> 0 | X28: =SUM(X21:X27) -> 0 | ... AA28: =SUM(AA21:AA27) -> 0 | AB28: =SUM(Q28:Z28) -> 12208.5
B50: 2025
B52: VENDAS HAVANNA | C52: MÊS | D52: PEÇAS | E52: VALORES
C53: JANEIRO
C54: FEVEREIRO
C55: MARÇO
C56: ABRIL | D56: 323 | E56: 14395.5
C57: MAIO | D57: 183 | E57: 6739.5
C58: JUNHO | D58: 140 | E58: 5457
C59: JULHO | D59: 400 | E59: 15117.5
C60: AGOSTO | D60: 165 | E60: 7687.25
C61: SETEMBRO | D61: 27 | E61: 1193.5
C62: OUTUBRO | D62: 307 | E62: 11683
C63: NOVEMBRO | D63: 49 | E63: 1873.25
C64: DEZEMBRO | D64: 41 | E64: 1768.25
C65: TOTAL | D65: =SUM(D53:D64) -> 1635 | E65: =SUM(E53:F64) -> 65914.75
...

Sheet PEDIDOS DO MÊS
A2: SEMANA DO PEDIDO | B2: (Tudo)
E4: Valores
A5: Anos (DATA DO PEDIDO) | B5: DATA DO PEDIDO | C5: CLIENTE | D5: PEDIDO | E5: Soma de QTD | F5: Soma de TOTAL
A6: 2026 | B6: 46266 | C6: CAPOBIANGO | D6: 254 | E6: 5 | F6: 216
C7: ROYAL BEAUTY | D7: 253 | E7: 250 | F7: 4125
B8: 46267 | C8: KPRO | D8: 1163 | E8: 500 | F8: 5750
B9: 46268 | C9: BUBBLES PET | D9: 1164 | E9: 300 | F9: 7350
A10: Total Geral | E10: 1055 | F10: 17441

Sheet PCP + MO 
A1: VENDEDOR | B1: PEDIDO | C1: DATA DO PEDIDO | D1: SEMANA DO PEDIDO | E1: CATEGORIA | F1: CLIENTE | G1: PRODUTO | H1: GRUPO | I1: LINHA | J1: QTD | K1: VALOR UNID | L1: TOTAL | M1: LIQUIDAÇÃO | N1: DATA ENTREGA | O1: SEMANA DE ENTREGA | P1: MATERIA PRIMA | Q1: ENTREGA | R1: MO CORTE | S1: MO SILK | T1: MO COSTURA | U1: MO EMBALAGEM | V1: TOTAL
A2: CONSERV | B2: 662 | C2: 45294 | D2: =WEEKNUM(C2) -> 1 | E2: COSMÉTICO | F2: M.D BOSO (PROHALL) | G2: AVENTAL OXFORD MODELO PADRÃO | H2: AVENTAL | I2: LEVE | J2: 200 | K2: 14 | L2: =J2*K2 -> 2800 | M2: 0 | N2: 45311 | O2: =WEEKNUM(N2) -> 3 | P2: OK | Q2: ENTREGUE | R2: =J2*0.25 -> 50 | S2: =J2*0.7 -> 140 | T2: =J2*1.5 -> 300 | U2: =J2*0.5 -> 100 | V2: =R2+S2+T2+U2 -> 590
A3: CONSERV | B3: 1099 | C3: 45297 | D3: =WEEKNUM(C3) -> 1 | E3: PET | F3: CEQ (PET SOCIETY) | G3: AVENTAL NYLON EMBORRACHADO CA 45305 | H3: AVENTAL | I3: LEVE | J3: 2500 | K3: 23.5 | L3: =J3*K3 -> 58750 | M3: 0 | N3: 45339 | O3: =WEEKNUM(N3) -> 7 | Q3: ENTREGUE | R3: =J3*0.25 -> 625 | S3: =J3*1 -> 2500 | T3: =J3*1.65 -> 4125 | U3: =J3*0.5 -> 1250 | V3: =R3+S3+T3+U3 -> 8500
A4: CONSERV | B4: 1101 | C4: 45297 | D4: =WEEKNUM(C4) -> 1 | E4: HAVANNA | F4: PATAGONIA CAFÉ LTDA | G4: CAMISETA MALHA 100% ALGODÃO | H4: CAMISETA | I4: LEVE | J4: 16 | K4: 36.75 | L4: =K4*J4 -> 588 | M4: 0 | N4: 45297 | O4: =WEEKNUM(N4) -> 1 | Q4: ENTREGUE
A5: CONSERV | B5: 911 | C5: 45412 | D5: =WEEKNUM(C5) -> 18 | E5: HAVANNA | F5: DGA DOCES | G5: SACOLA DE LONITA MODELO HAVANNA | H5: SACOLA | I5: PESADA | J5: 250 | K5: 16.5 | L5: =K5*J5 -> 4125 | M5: 0 | N5: 45428 | O5: =WEEKNUM(N5) -> 20 | Q5: ENTREGUE
A6: CONSERV | B6: 904 | C6: 45419 | D6: =WEEKNUM(C6) -> 19 | E6: HAVANNA | F6: DGA DOCES | G6: CAMISETA MALHA 100% ALGODÃO | H6: CAMISETA | I6: LEVE | J6: 500 | K6: 26.8 | L6: =K6*J6 -> 13400 | M6: 0 | N6: 45448 | O6: =WEEKNUM(N6) -> 23 | Q6: ENTREGUE
A7: CONSERV | B7: 912 | C7: 45421 | D7: =WEEKNUM(C7) -> 19 | E7: HAVANNA | F7: DGA DOCES | G7: SACOLA SUBLIMADA TECIDO PET | H7: SACOLA | I7: PESADA | J7: 250 | K7: 19 | L7: =K7*J7 -> 4750 | M7: 0 | N7: 45429 | O7: =WEEKNUM(N7) -> 20 | Q7: ENTREGUE
A8: CONSERV | B8: 929 | C8: 45440 | D8: =WEEKNUM(C8) -> 22 | E8: HAVANNA | F8: CAFÉ DEL PLATA | G8: CAMISETA MANGA LONGA 100% ALGODÃO | H8: CAMISETA | I8: LEVE | J8: 7 | K8: 47.5 | L8: =K8*J8 -> 332.5 | M8: 0 | N8: 45450 | O8: =WEEKNUM(N8) -> 23 | Q8: ENTREGUE
A9: CONSERV | B9: 929 | C9: 45440 | D9: =WEEKNUM(C9) -> 22 | E9: HAVANNA | F9: CAFÉ DEL PLATA | G9: CAMISETA MALHA 100% ALGODÃO | H9: CAMISETA | I9: LEVE | J9: 7 | K9: 33.88 | L9: =K9*J9 -> 237.16 | M9: 0 | N9: 45450 | O9: =WEEKNUM(N9) -> 23 | Q9: ENTREGUE
A10: CONSERV | B10: 929 | C10: 45440 | D10: =WEEKNUM(C10) -> 22 | E10: HAVANNA | F10: CAFÉ DEL PLATA | G10: CAMISETA MALHA 100% ALGODÃO BABY LOOK | H10: CAMISETA | I10: LEVE | J10: 4 | K10: 33.88 | L10: =K10*J10 -> 135.52 | M10: 0 | N10: 45450 | O10: =WEEKNUM(N10) -> 23 | Q10: ENTREGUE
A11: CONSERV | B11: 929 | C11: 45440 | D11: =WEEKNUM(C11) -> 22 | E11: HAVANNA | F11: CAFÉ DEL PLATA | G11: CAMISETA MANGA LONGA 100% ALGODÃO BABY LOOK | H11: CAMISETA | I11: LEVE | J11: 4 | K11: 47.5 | L11: =K11*J11 -> 190 | M11: 0 | N11: 45450 | O11: =WEEKNUM(N11) -> 23 | Q11: ENTREGUE
A12: CONSERV | B12: 928 | C12: 45440 | D12: =WEEKNUM(C12) -> 22 | E12: HAVANNA | F12: CAFÉ DEL PLATA | G12: CAMISETA MANGA LONGA 100% ALGODÃO | H12: CAMISETA | I12: LEVE | J12: 7 | K12: 47.5 | L12: =K12*J12 -> 332.5 | M12: 0 | N12: 45450 | O12: =WEEKNUM(N12) -> 23 | Q12: ENTREGUE
A13: CONSERV | B13: 928 | C13: 45440 | D13: =WEEKNUM(C13) -> 22 | E13: HAVANNA | F13: CAFÉ DEL PLATA | G13: CAMISETA MALHA 100% ALGODÃO | H13: CAMISETA | I13: LEVE | J13: 7 | K13: 33.88 | L13: =K13*J13 -> 237.16 | M13: 0 | N13: 45450 | O13: =WEEKNUM(N13) -> 23 | Q13: ENTREGUE
A14: CONSERV | B14: 928 | C14: 45440 | D14: =WEEKNUM(C14) -> 22 | E14: HAVANNA | F14: CAFÉ DEL PLATA | G14: CAMISETA MALHA 100% ALGODÃO BABY LOOK | H14: CAMISETA | I14: LEVE | J14: 4 | K14: 33.88 | L14: =K14*J14 -> 135.52 | M14: 0 | N14: 45450 | O14: =WEEKNUM(N14) -> 23 | Q14: ENTREGUE
A15: CONSERV | B15: 928 | C15: 45440 | D15: =WEEKNUM(C15) -> 22 | E15: HAVANNA | F15: CAFÉ DEL PLATA | G15: CAMISETA MANGA LONGA 100% ALGODÃO BABY LOOK | H15: CAMISETA | I15: LEVE | J15: 4 | K15: 47.5 | L15: =K15*J15 -> 190 | M15: 0 | N15: 45450 | O15: =WEEKNUM(N15) -> 23 | Q15: ENTREGUE
... A27: CONSERV | B27: 946 | C27: 45485 | D27: =WEEKNUM(C27) -> 28 | E27: HAVANNA | F27: LECEVY COMERCIO DE ALIMENTOS | G27: CAMISETA MANGA LONGA MALHA 100% ALGODÃO | H27: CAMISETA | I27: LEVE | J27: 6 | K27: 48.5 | L27: =K27*J27 -> 291 | M27: 0 | N27: 45527 | O27: =WEEKNUM(N27) -> 34 | Q27: ENTREGUE
A28: CONSERV | B28: 947 | C28: 45490 | D28: =WEEKNUM(C28) -> 29 | E28: HAVANNA | F28: JS ALIMENTAÇÃO | G28: CALÇA LEGGING | H28: CALÇA | I28: LEVE | J28: 10 | K28: 65 | L28: =K28*J28 -> 650 | M28: =L28 -> 650 | N28: 46260 | Q28: ENTREGUE
A29: CONSERV | B29: 947 | C29: 45490 | D29: =WEEKNUM(C29) -> 29 | E29: HAVANNA | F29: JS ALIMENTAÇÃO | G29: CAMISETA MALHA PV GOLA CARECA | H29: CAMISETA | I29: LEVE | J29: 10 | K29: 48.5 | L29: =K29*J29 -> 485 | M29: =L29 -> 485 | N29: 46260 | Q29: ENTREGUE
A30: CONSERV | B30: 947 | C30: 45490 | D30: =WEEKNUM(C30) -> 29 | E30: HAVANNA | F30: JS ALIMENTAÇÃO | G30: AVENTAL OXFORD MODELO PADRÃO | H30: AVENTAL | I30: LEVE | J30: 15 | K30: 62 | L30: =K30*J30 -> 930 | M30: =L30 -> 930 | N30: 46260 | Q30: ENTREGUE
A31: CONSERV | B31: 947 | C31: 45490 | D31: =WEEKNUM(C31) -> 29 | E31: HAVANNA | F31: JS ALIMENTAÇÃO | G31: FAIXA DE CABELO | H31: FAIXA | I31: LEVE | J31: 15 | K31: 21 | L31: =K31*J31 -> 315 | M31: =L31 -> 315 | N31: 46260 | Q31: ENTREGUE
A32: CONSERV | B32: 967 | C32: 45498 | D32: =WEEKNUM(C32) -> 30 | E32: HAVANNA | F32: J.A DA CAMARA FERNANDES | G32: BLUSA DE MOLETOM | H32: AVENTAL | I32: LEVE | J32: 17 | K32: 79.1 | L32: =K32*J32 -> 1344.7 | M32: 0 | N32: 45531 | O32: =WEEKNUM(N32) -> 35 | Q32: ENTREGUE
A33: CONSERV | B33: 967 | C33: 45498 | D33: =WEEKNUM(C33) -> 30 | E33: HAVANNA | F33: J.A DA CAMARA FERNANDES | G33: BLUSA DE MOLETOM | H33: MOLETOM | I33: LEVE | J33: 7 | K33: 62 | L33: =K33*J33 -> 434 | M33: 0 | N33: 45531 | O33: =WEEKNUM(N33) -> 35 | Q33: ENTREGUE
A34: CONSERV | B34: 970 | C34: 45506 | D34: =WEEKNUM(C34) -> 31 | E34: HAVANNA | F34: H4 CAFES E ALIMENTOS | G34: AVENTAL OXFORD MODELO PADRÃO | H34: AVENTAL | I34: LEVE | J34: 10 | K34: 62 | L34: =K34*J34 -> 620 | M34: 0 | N34: 45534 | O34: =WEEKNUM(N34) -> 35 | Q34: ENTREGUE
A35: CONSERV | B35: 970 | C35: 45506 | D35: =WEEKNUM(C35) -> 31 | E35: HAVANNA | F35: H4 CAFES E ALIMENTOS | G35: CAMISETA MALHA PV BABY LOOK | H35: CAMISETA | I35: LEVE | J35: 6 | K35: 48.9 | L35: =K35*J35 -> 293.4 | M35: 0 | N35: 45534 | O35: =WEEKNUM(N35) -> 35 | Q35: ENTREGUE
A36: CONSERV | B36: 970 | C36: 45506 | D36: =WEEKNUM(C36) -> 31 | E36: HAVANNA | F36: H4 CAFES E ALIMENTOS | G36: CALÇA LEGGING | H36: CALÇA | I36: LEVE | J36: 8 | K36: 65 | L36: =K36*J36 -> 520 | M36: 0 | N36: 45534 | O36: =WEEKNUM(N36) -> 35 | Q36: ENTREGUE
A37: CONSERV | B37: 970 | C37: 45506 | D37: =WEEKNUM(C37) -> 31 | E37: HAVANNA | F37: H4 CAFES E ALIMENTOS | G37: FAIXA DE CABELO | H37: FAIXA | I37: LEVE | J37: 6 | K37: 21 | L37: =K37*J37 -> 126 | M37: 0 | N37: 45534 | O37: =WEEKNUM(N37) -> 35 | Q37: ENTREGUE
A38: CONSERV | B38: 970 | C38: 45506 | D38: =WEEKNUM(C38) -> 31 | E38: HAVANNA | F38: H4 CAFES E ALIMENTOS | G38: CAMISETA MALHA PV GOLA CARECA | H38: CAMISETA | I38: LEVE | J38: 9 | K38: 48.5 | L38: =K38*J38 -> 436.5 | M38: 0 | N38: 45534 | O38: =WEEKNUM(N38) -> 35 | Q38: ENTREGUE
A39: CONSERV | B39: 966 | C39: 45509 | D39: =WEEKNUM(C39) -> 32 | E39: HAVANNA | F39: JSC CAFETERIA LTDA | G39: CAMISETA MALHA 100% ALGODÃO BABY LOOK | H39: CAMISETA | I39: LEVE | J39: 2 | K39: 48.5 | L39: =K39*J39 -> 97 | M39: 0 | N39: 45510 | O39: =WEEKNUM(N39) -> 32 | Q39: ENTREGUE
A40: CONSERV | B40: 966 | C40: 45509 | D40: =WEEKNUM(C40) -> 32 | E40: HAVANNA | F40: JSC CAFETERIA LTDA | G40: AVENTAL OXFORD MODELO PADRÃO | H40: AVENTAL | I40: LEVE | J40: 1 | K40: 62 | L40: =K40*J40 -> 62 | M40: 0 | N40: 45510 | O40: =WEEKNUM(N40) -> 32 | Q40: ENTREGUE
A41: CONSERV | B41: 966 | C41: 45509 | D41: =WEEKNUM(C41) -> 32 | E41: HAVANNA | F41: JSC CAFETERIA LTDA | G41: CAMISETA MALHA PV | H41: CAMISETA | I41: LEVE | J41: 2 | K41: 48.5 | L41: =K41*J41 -> 97 | M41: 0 | N41: 45510 | O41: =WEEKNUM(N41) -> 32 | Q41: ENTREGUE
A42: CONSERV | B42: 966 | C42: 45509 | D42: =WEEKNUM(C42) -> 32 | E42: HAVANNA | F42: JSC CAFETERIA LTDA | G42: CALÇA LEGGING | H42: CALÇA | I42: LEVE | J42: 1 | K42: 65 | L42: =K42*J42 -> 65 | M42: 0 | N42: 45510 | O42: =WEEKNUM(N42) -> 32 | Q42: ENTREGUE
A43: CONSERV | B43: 966 | C43: 45509 | D43: =WEEKNUM(C43) -> 32 | E43: HAVANNA | F43: JSC CAFETERIA LTDA | G43: FAIXA DE CABELO | H43: FAIXA | I43: LEVE | J43: 5 | K43: 21 | L43: =K43*J43 -> 105 | M43: 0 | N43: 45510 | O43: =WEEKNUM(N43) -> 32 | Q43: ENTREGUE
... A160: CONSERV | B160: 1065 | C160: 45615 | D160: =WEEKNUM(C160) -> 47 | E160: HAVANNA | F160: MAV COMERCIO DE ALIMENTOS | G160: FAIXA DE CABELO | H160: FAIXA | I160: LEVE | J160: 8 | K160: 21 | L160: =K160*J160 -> 168 | M160: 0 | N160: 45636 | O160: =WEEKNUM(N160) -> 50 | Q160: ENTREGUE
A161: CONSERV | B161: 1068 | C161: 45617 | D161: =WEEKNUM(C161) -> 47 | E161: HAVANNA | F161: HAVANNA RT | G161: CALÇA LEGGING | H161: CALÇA | I161: LEVE | J161: 9 | K161: 75 | L161: =J161*K161 -> 675 | M161: 0 | N161: 45663 | O161: =WEEKNUM(N161) -> 2 | P161: OK | Q161: ENTREGUE | R161: =J161*0.25 -> 2.25 | T161: =J161*3 -> 27 | U161: =J161*0.5 -> 4.5 | V161: =R161+S161+T161+U161 -> 33.75
A162: CONSERV | B162: 1067 | C162: 45617 | D162: =WEEKNUM(C162) -> 47 | E162: HAVANNA | F162: J.A DA CAMARA FERNANDES | G162: CAMISETA MALHA 100% ALGODÃO | H162: CAMISETA | I162: LEVE | J162: 8 | K162: 36.75 | L162: =K162*J162 -> 294 | M162: 0 | N162: 45660 | O162: =WEEKNUM(N162) -> 1 | Q162: ENTREGUE
A163: CONSERV | B163: 1067 | C163: 45617 | D163: =WEEKNUM(C163) -> 47 | E163: HAVANNA | F163: J.A DA CAMARA FERNANDES | G163: CALÇA BRIM | H163: CALÇA | I163: PESADA | J163: 8 | K163: 75 | L163: =K163*J163 -> 600 | M163: 0 | N163: 45660 | O163: =WEEKNUM(N163) -> 1 | Q163: ENTREGUE
A164: CONSERV | B164: 1067 | C164: 45617 | D164: =WEEKNUM(C164) -> 47 | E164: HAVANNA | F164: J.A DA CAMARA FERNANDES | G164: CAMISETA MALHA 100% ALGODÃO BABY LOOK | H164: CAMISETA | I164: LEVE | J164: 12 | K164: 36.75 | L164: =K164*J164 -> 441 | M164: 0 | N164: 45660 | O164: =WEEKNUM(N164) -> 1 | Q164: ENTREGUE
A165: CONSERV | B165: 1067 | C165: 45617 | D165: =WEEKNUM(C165) -> 47 | E165: HAVANNA | F165: J.A DA CAMARA FERNANDES | G165: CALÇA LEGGING | H165: CALÇA | I165: LEVE | J165: 12 | K165: 65 | L165: =K165*J165 -> 780 | M165: 0 | N165: 45660 | O165: =WEEKNUM(N165) -> 1 | Q165: ENTREGUE
A166: CONSERV | B166: 1067 | C166: 45617 | D166: =WEEKNUM(C166) -> 47 | E166: HAVANNA | F166: J.A DA CAMARA FERNANDES | G166: FAIXA DE CABELO | H166: FAIXA | I166: LEVE | J166: 8 | K166: 21 | L166: =K166*J166 -> 168 | M166: 0 | N166: 45660 | O166: =WEEKNUM(N166) -> 1 | Q166: ENTREGUE
A167: CONSERV | B167: 1067 | C167: 45617 | D167: =WEEKNUM(C167) -> 47 | E167: HAVANNA | F167: J.A DA CAMARA FERNANDES | G167: AVENTAL OXFORD MODELO PADRÃO | H167: AVENTAL | I167: LEVE | J167: 12 | K167: 25 | L167: =K167*J167 -> 300 | M167: 0 | N167: 45660 | O167: =WEEKNUM(N167) -> 1 | Q167: ENTREGUE
...

Sheet VENDAS 2026
A1: CARTEIRA EM PRODUÇÃO | D1: TICKTI MÉDIO
A2: Peças | B2: ='PCP + MO '!J1629 -> 24489 | D2: =B3/B2 -> 17.136449
A3: Faturar | B3: ='PCP + MO '!L1629 -> 419654.5 | I3: —
A4: Liquidar | B4: ='PCP + MO '!M1629 -> 246959.5
A6: VENDAS 2026
A7: MÊS | B7: QUANT PEDIDOS | C7: ITENS | D7: VALOR TOTAL | E7: TICTIK MÉDIO
A8: JANEIRO | B8: 39 | C8: 13275 | D8: 257139.2 | E8: =D8/C8 -> 19.370185
A9: FEVEREIRO | B9: 39 | C9: 12509 | D9: 231893.5 | E9: =D9/C9 -> 18.538133
A10: MARÇO | B10: 55 | C10: 44179 | D10: 588929 | E10: =D10/C10 -> 13.330519
A11: ABRIL | B11: 31 | C11: 13879 | D11: 228088.5 | E11: =D11/C11 -> 16.434073
A12: MAIO | B12: 43 | C12: 14040 | D12: 316137.8 | E12: =D12/C12 -> 22.516937
A13: JUNHO | B13: 41 | C13: 9241 | D13: 160954.25 | E13: =D13/C13 -> 17.417406
A14: JULHO | B14: 51 | C14: 23992 | D14: 444060.04 | E14: =D14/C14 -> 18.508671
A15: AGOSTO
A16: SETEMBRO
A17: OUTUBRO
A18: NOVEMBRO
A19: DEZEMBRO
A20: TOTAL | B20: =SUM(B8:B19) -> 299 | C20: =SUM(C8:C19) -> 131115 | D20: =SUM(D8:D19) -> 2227202.3

Sheet PEDIDOS EM ABERTO HAVANNA
A1: PEDIDO HAVANNA 237 - HVNN ONE COMERCIO
A2: PRODUTO | B2: TAM | C2: QUANT
A3: POLO FEMININA | B3: P | C3: 1
A4: POLO FEMININA | B4: M | C4: 1
A5: POLO FEMININA | B5: G | C5: 1
A6: POLO | B6: M | C6: 1
A8: PEDIDO HAVANNA 241 - PATAGONIA CAFÉ
A9: PRODUTO | B9: TAM | C9: QUANT
A10: CAMISETA | B10: G | C10: 6
A11: CAMISETA | B11: GG | C11: 6
A12: CAMISETA MANGA LONGA | B12: G | C12: 1
A13: CAMISETA MANGA LONGA | B13: GG | C13: 1
A14: BLUSA MOLETOM | B14: G | C14: 1
A15: BLUSA MOLETOM | B15: GG | C15: 1
A16: AVENTAL | C16: 4
A18: PEDIDO HAVANNA 244 - CAFÉ E DOCES
A19: PRODUTO | B19: TAM | C19: QUANT
A20: AVENTAL | C20: 6
A21: FAIXA DE CABELO | C21: 4
A22: CAMISETA BABY LOOK | B22: M | C22: 4
A23: CALÇA BRIM | B23: P | C23: 2
A24: CALÇA BRIM | B24: M | C24: 2
A26: PEDIDO HAVANNA 254 - CAPOBIANGO
A27: PRODUTO | B27: TAM | C27: QUANT
A28: BABY LOOK | B28: M | C28: 2
A29: BABY LOOK MANGA LONGA | B29: M | C29: 1
A30: BABY LOOK MANGA LONGA | B30: G | C30: 1
A31: BABY LOOK MANGA LONGA | B31: GG | C31: 1
